I'm sorry, but an uncaught exception occurred.

After initialization, but before game start.
PermissionError: [WinError 32] プロセスはファイルにアクセスできません。別のプロセスが使用中です。: 'C:\\Users\\tamon\\Desktop\\RenPyProject\\risa_p1\\game\\saves\\navigation.json.new' -> 'C:\\Users\\tamon\\Desktop\\RenPyProject\\risa_p1\\game\\saves\\navigation.json'

-- Full Traceback ------------------------------------------------------------

Full traceback:
  File "C:\Users\tamon\Downloads\renpy-8.3.1-sdk\renpy\bootstrap.py", line 359, in bootstrap
    renpy.main.main()
  File "C:\Users\tamon\Downloads\renpy-8.3.1-sdk\renpy\main.py", line 599, in main
    renpy.dump.dump(False)
  File "C:\Users\tamon\Downloads\renpy-8.3.1-sdk\renpy\dump.py", line 262, in dump
    os.rename(new, filename)
PermissionError: [WinError 32] プロセスはファイルにアクセスできません。別のプロセスが使用中です。: 'C:\\Users\\tamon\\Desktop\\RenPyProject\\risa_p1\\game\\saves\\navigation.json.new' -> 'C:\\Users\\tamon\\Desktop\\RenPyProject\\risa_p1\\game\\saves\\navigation.json'

Windows-10-10.0.26100 AMD64
Ren'Py 8.3.1.24090601
risa_p1 1.0
Thu Mar 27 20:31:30 2025
